Workbook

Sheet About
A1: Vendor Invoice Reconciliation – Print & Post (synthetic data)
A2: Purpose: reconcile AP invoices against purchase orders, vendor master and bank payments; flag data-quality issues; summarize spend by vendor.
A3: As-of date (blue = input you may change): | B3: 46295
A5: Sheets
A6: Findings – headline numbers, charts and recommendations.
A7: Vendors / POs / Payments / Invoices – cleaned source tables, produced by the Power Query scripts in /power_query.
A8: Vendor_Aliases – reference table mapping every vendor spelling seen in AP to a VendorID (data catalog).
A9: Checks – one row per invoice with lookup columns and validation flags (red fill = issue).
A10: Payment_Checks – flags payments that do not match any invoice.
A11: Mapping_Checks – flags gaps in the application / document-type / vendor map.
A12: Issues_Summary – count and dollar value of every issue type.
A13: Vendor_Summary – invoiced, paid, outstanding and issue counts per vendor.
A14: Data_Dictionary – every field, its source and its rule.
A15: Lookups use INDEX/MATCH so the file works in every Excel version (XLOOKUP equivalents are listed in the README).
A16: All data is synthetic, generated for practice. No real company data.

Sheet Findings
A1: Key findings (as of 2026-09-30)
A3: Invoice rows reviewed | B3: =Issues_Summary!B19 -> 96
A4: Invoices with at least one issue | B4: =Issues_Summary!B18 -> 42
A5: Share of invoices with an issue | B5: =B4/B3 -> 0.4375
A6: Invoiced total (excl. duplicates) | B6: =Vendor_Summary!E13 -> 654664.51
A7: Paid to date | B7: =Vendor_Summary!F13 -> 440973.24
A8: Outstanding | B8: =Vendor_Summary!G13 -> 213691.27
A9: Unpaid & past due | B9: =Issues_Summary!C12 -> 172409.58
A10: Duplicate invoices at risk of double payment | B10: =Issues_Summary!C2 -> 37619.05
A12: Recommendations
A13: 1. Block payment on the 4 duplicate invoices and ask AP to void them before the next payment run.
A14: 2. Require a PO amendment before approving the 5 invoices that push 3 POs over their approved amount.
A15: 3. Send the 5 invoices where net + tax does not equal the total back to vendors for correction.
A16: 4. Review the 20 unpaid past-due invoices with AP; prioritize the largest balances in Vendor_Summary.
A17: 5. Trace the 2 orphan payments and 2 short/over payments with Treasury.
A18: 6. Decide whether the 2 vendors missing from the master should be onboarded; stop new work with the 2 inactive vendors still invoicing and still mapped (7 mapping rows).
A19: 7. Prevent alias drift: replace free-text vendor entry in AP with a dropdown sourced from the vendor master.
A20: 8. Fill the 5 missing mail vendors and 5 missing owners in the application / document-type map.

Sheet Vendors
A1: VendorID | B1: VendorName | C1: Category | D1: PaymentTerms | E1: Status | F1: Province | G1: TaxRate | H1: TermDays | J1: Province | K1: Sales tax rate
A2: V001 | B2: Northbridge Print Services | C2: Print | D2: Net30 | E2: Active | F2: ON | G2: =INDEX($K$2:$K$5,MATCH(F2,$J$2:$J$5,0)) -> 0.13 | H2: =VALUE(SUBSTITUTE(D2,"Net","")) -> 30 | J2: ON | K2: 0.13
A3: V002 | B3: Maple Mailing Solutions | C3: Mail Processing | D3: Net30 | E3: Active | F3: ON | G3: =INDEX($K$2:$K$5,MATCH(F3,$J$2:$J$5,0)) -> 0.13 | H3: =VALUE(SUBSTITUTE(D3,"Net","")) -> 30 | J3: QC | K3: 0.14975
A4: V003 | B4: Lakeshore Envelope Co. | C4: Envelope Supply | D4: Net45 | E4: Active | F4: ON | G4: =INDEX($K$2:$K$5,MATCH(F4,$J$2:$J$5,0)) -> 0.13 | H4: =VALUE(SUBSTITUTE(D4,"Net","")) -> 45 | J4: BC | K4: 0.12
A5: V004 | B5: Summit Digital Print Inc. | C5: Print | D5: Net30 | E5: Active | F5: QC | G5: =INDEX($K$2:$K$5,MATCH(F5,$J$2:$J$5,0)) -> 0.14975 | H5: =VALUE(SUBSTITUTE(D5,"Net","")) -> 30 | J5: AB | K5: 0.05
A6: V005 | B6: Harbourview Postage Ltd. | C6: Postage | D6: Net15 | E6: Active | F6: ON | G6: =INDEX($K$2:$K$5,MATCH(F6,$J$2:$J$5,0)) -> 0.13 | H6: =VALUE(SUBSTITUTE(D6,"Net","")) -> 15
A7: V006 | B7: Cedarline Paper Supply | C7: Paper | D7: Net45 | E7: Active | F7: ON | G7: =INDEX($K$2:$K$5,MATCH(F7,$J$2:$J$5,0)) -> 0.13 | H7: =VALUE(SUBSTITUTE(D7,"Net","")) -> 45 | J7: Source: HST/GST/QST combined rates by province (2026), assumption for this exercise
A8: V007 | B8: Redwood Document Services | C8: Print | D8: Net30 | E8: Inactive | F8: BC | G8: =INDEX($K$2:$K$5,MATCH(F8,$J$2:$J$5,0)) -> 0.12 | H8: =VALUE(SUBSTITUTE(D8,"Net","")) -> 30
A9: V008 | B9: ClearPath Fulfillment | C9: Fulfillment | D9: Net30 | E9: Active | F9: ON | G9: =INDEX($K$2:$K$5,MATCH(F9,$J$2:$J$5,0)) -> 0.13 | H9: =VALUE(SUBSTITUTE(D9,"Net","")) -> 30
A10: V009 | B10: Granite Press Ltd. | C10: Print | D10: Net60 | E10: Active | F10: AB | G10: =INDEX($K$2:$K$5,MATCH(F10,$J$2:$J$5,0)) -> 0.05 | H10: =VALUE(SUBSTITUTE(D10,"Net","")) -> 60
A11: V010 | B11: Bluewater Data Mail | C11: Mail Processing | D11: Net30 | E11: Inactive | F11: ON | G11: =INDEX($K$2:$K$5,MATCH(F11,$J$2:$J$5,0)) -> 0.13 | H11: =VALUE(SUBSTITUTE(D11,"Net","")) -> 30

Sheet Vendor_Aliases
A1: AliasKey (UPPER, trimmed) | B1: VendorID
A2: NORTHBRIDGE PRINT SERVICES | B2: V001
A3: NORTHBRIDGE PRINT | B3: V001
A4: NORTHBRIDGE PRINT SERVICES INC | B4: V001
A5: MAPLE MAILING SOLUTIONS | B5: V002
A6: MAPLE MAILING | B6: V002
A7: LAKESHORE ENVELOPE CO. | B7: V003
A8: LAKESHORE ENVELOPE COMPANY | B8: V003
A9: SUMMIT DIGITAL PRINT INC. | B9: V004
A10: SUMMIT DIGITAL PRINT | B10: V004
A11: HARBOURVIEW POSTAGE LTD. | B11: V005
A12: HARBOURVIEW POSTAGE | B12: V005
... A25: BLUEWATER DATAMAIL | B25: V010

Sheet POs
A1: PO_Number | B1: VendorID | C1: Application | D1: DocumentType | E1: Approved_Amount | F1: PO_Date | G1: Approver
A2: PO-4501 | B2: V007 | C2: Group Retirement | D2: Policy Package | E2: 7700 | F2: 46033 | G2: R. Singh
A3: PO-4502 | B3: V007 | C3: Banking | D3: Annual Statement | E3: 17100 | F3: 46200 | G3: L. Martin
A4: PO-4503 | B4: V010 | C4: Individual Insurance | D4: Mail Insertion | E4: 7950 | F4: 46034 | G4: T. Abebe
A5: PO-4505 | B5: V010 | C5: Banking | D5: Mail Insertion | E5: 7600 | F5: 46210 | G5: L. Martin
A6: PO-4506 | B6: V005 | C6: Group Benefits | D6: Postage | E6: 10700 | F6: 46221 | G6: M. Chen
A7: PO-4508 | B7: V003 | C7: Group Retirement | D7: Envelopes | E7: 4350 | F7: 46222 | G7: L. Martin
A8: PO-4511 | B8: V002 | C8: Group Retirement | D8: Mail Insertion | E8: 3100 | F8: 46243 | G8: L. Martin
A9: PO-4515 | B9: V002 | C9: Banking | D9: Mail Insertion | E9: 18050 | F9: 46047 | G9: M. Chen
A10: PO-4516 | B10: V004 | C10: Group Benefits | D10: Tax Slip (T4A/T5) | E10: 4000 | F10: 46038 | G10: R. Singh
A11: PO-4520 | B11: V002 | C11: Wealth & Asset Mgmt | D11: Mail Insertion | E11: 6150 | F11: 46098 | G11: M. Chen
A12: PO-4522 | B12: V006 | C12: Group Retirement | D12: Paper Stock | E12: 17550 | F12: 46198 | G12: R. Singh
A13: PO-4524 | B13: V004 | C13: Wealth & Asset Mgmt | D13: Tax Slip (T4A/T5) | E13: 18350 | F13: 46145 | G13: R. Singh
... A61: PO-4637 | B61: V006 | C61: Group Retirement | D61: Paper Stock | E61: 16850 | F61: 46056 | G61: M. Chen

Sheet Invoices
A1: InvoiceNo | B1: VendorRaw | C1: PO_Number | D1: InvoiceDate | E1: NetAmount | F1: Tax | G1: InvoiceTotal
A2: INV-10041 | B2: Maple Mailing | C2: PO-4527 | D2: 46183 | E2: 7976.03 | F2: 1036.88 | G2: 9012.91
A3: INV-10175 | B3: Cedarline Paper | C3: PO-4629 | D3: 46270 | E3: 2776.31 | F3: 360.92 | G3: 3137.23
A4: INV-10164 | B4: Northbridge Print Services | C4: PO-4620 | D4: 46158 | E4: 6734.49 | F4: 875.48 | G4: 7609.97
A5: INV-10158 | B5: lakeshore envelope co. | C5: PO-4616 | D5: 46208 | E5: 2199.23 | F5: 285.9 | G5: 2485.13
A6: INV-10079 | B6: Lakeshore Envelope Co. | C6: PO-4553 | D6: 46193 | E6: 7070.6 | F6: 919.18 | G6: 7989.78
A7: INV-10032 | B7: MAPLE MAILING SOLUTIONS | C7: PO-4520 | D7: 46118 | E7: 2372.87 | F7: 308.47 | G7: 2681.34
A8: INV-10111 | B8: Maple Mailing Solutions | C8: PO-4582 | D8: 46090 | E8: 13086 | F8: 1701.18 | G8: 14787.18
A9: INV-10077 | B9: Maple Mailing Solutions | C9: PO-4550 | D9: 46240 | E9: 4742.08 | F9: 616.47 | G9: 5358.55
A10: INV-10056 | B10: CLEARPATH FULFILMENT | C10: PO-4537 | D10: 46158 | E10: 6017.78 | F10: 782.31 | G10: 6800.09
A11: INV-10070 | B11: lakeshore envelope co. | C11: PO-4543 | D11: 46188 | E11: 1121.16 | F11: 145.75 | G11: 1266.91
A12: INV-10028 | B12: Summit Digital Print Inc. | C12: PO-4516 | D12: 46048 | E12: 3495.03 | F12: 523.38 | G12: 4018.41
A13: INV-10046 | B13: ClearPath Fulfillment | C13: PO-4531 | D13: 46075 | E13: 7344.57 | F13: 954.79 | G13: 8299.36
... A23: INV-10034 | B23: Summit Digital Print Inc. | C23: PO-4524 | D23: 46154 | E23: 9062.62 | F23: 1357.13 | G23: 10419.75
A24: INV-10131 | B24: lakeshore envelope co. | D24: 46176 | E24: 2087.85 | F24: 271.42 | G24: 2359.27
A25: INV-10013 | B25: Bluewater Datamail | C25: PO-4503 | D25: 46046 | E25: 2842.76 | F25: 369.56 | G25: 3212.32
A26: INV-10100 | B26: Granite Press Ltd. | C26: PO-4567 | D26: 46109 | E26: 6754.55 | F26: 337.73 | G26: 7092.28
A27: INV-10192 | B27: QuickPost Couriers | D27: 46256 | E27: 5998.08 | F27: 779.75 | G27: 6777.83
A28: INV-10122 | B28: Lakeshore Envelope Co. | C28: PO-4593 | D28: 46186 | E28: 11842.12 | F28: 1539.48 | G28: 13381.6
A29: INV-10063 | B29: Maple Mailing | C29: PO-4541 | D29: 46177 | E29: 735.56 | F29: 95.62 | G29: 831.18
A30: INV-10110 | B30: SUMMIT DIGITAL PRINT INC. | D30: 46152 | E30: 2819.93 | F30: 422.28 | G30: 3242.21
A31: INV-10108 | B31: Northbridge Print Services Inc | C31: PO-4575 | D31: 46220 | E31: 3143.01 | F31: 408.59 | G31: 3551.6
A32: INV-10188 | B32: CEDARLINE PAPER SUPPLY | C32: PO-4637 | D32: 46064 | E32: 15126.23 | F32: 1966.41 | G32: 17092.64
A33: INV-10057 | B33: Northbridge Print Services | C33: PO-4538 | D33: 46223 | E33: 8901.74 | F33: 1157.23 | G33: 10058.97
A34: INV-10140 | B34: Northbridge Print Services | C34: PO-4605 | D34: 46206 | E34: 4227.57 | F34: 549.58 | G34: 4777.15
A35: INV-10043 | B35: MAPLE MAILING SOLUTIONS | C35: PO-4527 | D35: 46210 | E35: 6604.78 | F35: 858.62 | G35: 7463.4
A36: INV-10067 | B36: lakeshore envelope co. | D36: 46218 | E36: 2076.69 | F36: 269.97 | G36: 2346.66
A37: INV-10096 | B37: Summit Digital Print Inc. | C37: PO-4563 | D37: 46244 | E37: 12038.5 | F37: 1802.77 | G37: 13841.27
A38: INV-10090 | B38: SUMMIT DIGITAL PRINT INC. | C38: PO-4560 | D38: 46079 | E38: 1292.2 | F38: 193.51 | G38: 1485.71
A39: INV-10183 | B39: Cedarline Paper Supply | C39: PO-4633 | D39: 46259 | E39: 1202.21 | F39: 156.29 | G39: 1358.5
A40: INV-10109 | B40: Summit Digital Print Inc. | C40: PO-4579 | D40: 46068 | E40: 7988.99 | F40: 1196.35 | G40: 9185.34
A41: INV-10113 | B41: Granite Press Ltd. | C41: PO-4586 | D41: 46146 | E41: 5861.11 | F41: 293.06 | G41: 6154.17
A42: INV-10021 | B42: Maple Mailing | C42: PO-4511 | D42: 46261 | E42: 2015 | F42: 261.95 | G42: 2236.95
A43: INV-10079 | B43: Lakeshore Envelope Co. | C43: PO-4553 | D43: 46193 | E43: 7070.6 | F43: 919.18 | G43: 7989.78
A44: INV-10171 | B44: Summit Digital Print | C44: PO-4625 | D44: 46256 | E44: 1236.27 | F44: 185.13 | G44: 1421.4
A45: INV-10060 | B45: NORTHBRIDGE PRINT SERVICES | C45: PO-4538 | D45: 46221 | E45: 6755.33 | F45: 878.19 | G45: 7633.52
A46: INV-10184 | B46: Cedarline Paper Supply | C46: PO-4633 | D46: 46277 | E46: 1025.86 | F46: 133.36 | G46: 1271.72
A47: INV-10061 | B47: Maple Mailing Solutions | C47: PO-4541 | D47: 46158 | E47: 973.64 | F47: 126.57 | G47: 1100.21
A48: INV-10064 | B48: Lakeshore Envelope Company | C48: PO-4542 | D48: 46201 | E48: 2603.01 | F48: 338.39 | G48: 2941.4
... A66: INV-10137 | B66: Maple Mailing | C66: PO-4600 | D66: 46203 | E66: 2061.14 | F66: 267.95 | G66: 2329.09
...

Sheet Payments
A1: PaymentRef | B1: InvoiceRef_Raw | C1: PaidDate | D1: PaidAmount | E1: Currency | F1: InvoiceNo_Key
A2: EFT880075 | B2: INV10036 | C2: 46182 | D2: 7662.95 | E2: CAD | F2: =IF(ISNUMBER(SEARCH("-",B2)),B2,"INV-"&MID(B2,4,20)) -> INV-10036
A3: EFT880312 | B3: INV-10145 | C3: 46149 | D3: 11363.34 | E3: CAD | F3: =IF(ISNUMBER(SEARCH("-",B3)),B3,"INV-"&MID(B3,4,20)) -> INV-10145
A4: EFT880220 | B4: INV-10071 | C4: 46251 | D4: 1070.42 | E4: CAD | F4: =IF(ISNUMBER(SEARCH("-",B4)),B4,"INV-"&MID(B4,4,20)) -> INV-10071
A5: EFT880139 | B5: INV-10067 | C5: 46260 | D5: 2346.66 | E5: CAD | F5: =IF(ISNUMBER(SEARCH("-",B5)),B5,"INV-"&MID(B5,4,20)) -> INV-10067
A6: EFT880063 | B6: INV10087 | C6: 46099 | D6: 2010.22 | E6: CAD | F6: =IF(ISNUMBER(SEARCH("-",B6)),B6,"INV-"&MID(B6,4,20)) -> INV-10087
A7: EFT880037 | B7: INV10070 | C7: 46229 | D7: 1266.91 | E7: CAD | F7: =IF(ISNUMBER(SEARCH("-",B7)),B7,"INV-"&MID(B7,4,20)) -> INV-10070
A8: EFT880206 | B8: INV-10010 | C8: 46092 | D8: 4414.68 | E8: CAD | F8: =IF(ISNUMBER(SEARCH("-",B8)),B8,"INV-"&MID(B8,4,20)) -> INV-10010
A9: EFT880043 | B9: INV-10046 | C9: 46095 | D9: 8299.36 | E9: CAD | F9: =IF(ISNUMBER(SEARCH("-",B9)),B9,"INV-"&MID(B9,4,20)) -> INV-10046
A10: EFT880317 | B10: INV-99001 | C10: 46277 | D10: 1005.11 | E10: CAD | F10: =IF(ISNUMBER(SEARCH("-",B10)),B10,"INV-"&MID(B10,4,20)) -> INV-99001
A11: EFT880026 | B11: INV-10077 | C11: 46260 | D11: 5358.55 | E11: CAD | F11: =IF(ISNUMBER(SEARCH("-",B11)),B11,"INV-"&MID(B11,4,20)) -> INV-10077
A12: EFT880190 | B12: INV-10159 | C12: 46243 | D12: 2075.32 | E12: CAD | F12: =IF(ISNUMBER(SEARCH("-",B12)),B12,"INV-"&MID(B12,4,20)) -> INV-10159
A13: EFT880070 | B13: INV-10023 | C13: 46290 | D13: 1821.56 | E13: CAD | F13: =IF(ISNUMBER(SEARCH("-",B13)),B13,"INV-"&MID(B13,4,20)) -> INV-10023
... A69: EFT880136 | B69: INV-10043 | C69: 46230 | D69: 3731.7 | E69: CAD | F69: =IF(ISNUMBER(SEARCH("-",B69)),B69,"INV-"&MID(B69,4,20)) -> INV-10043

Sheet Checks
A1: InvoiceNo | B1: VendorRaw | C1: VendorID | D1: VendorStatus | E1: PO_Number | F1: PO_VendorID | G1: PO_Approved | H1: InvoiceDate | I1: NetAmount | J1: Tax | K1: InvoiceTotal | L1: DueDate | M1: Is_Duplicate | N1: PO_Invoiced_ToDate | O1: Flag_UnknownVendor | P1: Flag_MissingPO | Q1: Flag_PO_NotFound | R1: Flag_PO_VendorMismatch | S1: Flag_OverPO | T1: Flag_TotalMismatch | U1: Flag_TaxRate | V1: Flag_InactiveVendor | W1: PaidAmount | X1: Flag_PaymentMismatch | Y1: Flag_OverdueUnpaid | Z1: IssueCount
A2: =Invoices!A2 -> INV-10041 | B2: =Invoices!B2 -> Maple Mailing | C2: =IFERROR(INDEX(Vendor_Aliases!$B$2:$B$25,MATCH(UPPER(TRIM(B2)),Vendor_Aliases!$A$2:$A$25,0)),"UNKNOWN") -> V002 | D2: =IFERROR(INDEX(Vendors!$E$2:$E$11,MATCH(C2,Vendors!$A$2:$A$11,0)),"") -> Active | E2: =IF(Invoices!C2="","",Invoices!C2) -> PO-4527 | F2: =IF(E2="","",IFERROR(INDEX(POs!$B$2:$B$61,MATCH(E2,POs!$A$2:$A$61,0)),"NOT FOUND")) -> V002 | G2: =IF(E2="","",IFERROR(INDEX(POs!$E$2:$E$61,MATCH(E2,POs!$A$2:$A$61,0)),"")) -> 18750 | H2: =Invoices!D2 -> 46183 | I2: =Invoices!E2 -> 7976.03 | J2: =Invoices!F2 -> 1036.88 | K2: =Invoices!G2 -> 9012.91 | L2: =IFERROR(H2+INDEX(Vendors!$H$2:$H$11,MATCH(C2,Vendors!$A$2:$A$11,0)),H2+30) -> 46213 | M2: =IF(COUNTIF($A$2:A2,A2)>1,1,0) -> 0 | N2: =IF(E2="","",SUMIFS($I$2:$I$97,$E$2:$E$97,E2,$M$2:$M$97,0)) -> 14580.81 | O2: =IF(C2="UNKNOWN",1,0) -> 0 | P2: =IF(E2="",1,0) -> 0 | Q2: =IF(F2="NOT FOUND",1,0) -> 0 | R2: =IF(AND(F2<>"",F2<>"NOT FOUND",F2<>C2),1,0) -> 0 | S2: =IF(AND(M2=0,ISNUMBER(G2),N2>G2),1,0) -> 0 | T2: =IF(ABS(I2+J2-K2)>0.01,1,0) -> 0 | U2: =IFERROR(IF(ABS(J2-ROUND(I2*INDEX(Vendors!$G$2:$G$11,MATCH(C2,Vendors!$A$2:$A$11,0)),2))>0.01,1,0),0) -> 0 | V2: =IF(D2="Inactive",1,0) -> 0 | W2: =SUMIFS(Payments!$D$2:$D$69,Payments!$F$2:$F$69,A2) -> 9012.91 | X2: =IF(AND(M2=0,W2>0,ABS(W2-K2)>0.01),1,0) -> 0 | Y2: =IF(AND(M2=0,W2=0,L2<About!$B$3),1,0) -> 0 | Z2: =M2+SUM(O2:V2)+X2+Y2 -> 0
A3: =Invoices!A3 -> INV-10175 | B3: =Invoices!B3 -> Cedarline Paper | C3: =IFERROR(INDEX(Vendor_Aliases!$B$2:$B$25,MATCH(UPPER(TRIM(B3)),Vendor_Aliases!$A$2:$A$25,0)),"UNKNOWN") -> V006 | D3: =IFERROR(INDEX(Vendors!$E$2:$E$11,MATCH(C3,Vendors!$A$2:$A$11,0)),"") -> Active | E3: =IF(Invoices!C3="","",Invoices!C3) -> PO-4629 | F3: =IF(E3="","",IFERROR(INDEX(POs!$B$2:$B$61,MATCH(E3,POs!$A$2:$A$61,0)),"NOT FOUND")) -> V006 | G3: =IF(E3="","",IFERROR(INDEX(POs!$E$2:$E$61,MATCH(E3,POs!$A$2:$A$61,0)),"")) -> 6050 | H3: =Invoices!D3 -> 46270 | I3: =Invoices!E3 -> 2776.31 | J3: =Invoices!F3 -> 360.92 | K3: =Invoices!G3 -> 3137.23 | L3: =IFERROR(H3+INDEX(Vendors!$H$2:$H$11,MATCH(C3,Vendors!$A$2:$A$11,0)),H3+30) -> 46315 | M3: =IF(COUNTIF($A$2:A3,A3)>1,1,0) -> 0 | N3: =IF(E3="","",SUMIFS($I$2:$I$97,$E$2:$E$97,E3,$M$2:$M$97,0)) -> 4929.19 | O3: =IF(C3="UNKNOWN",1,0) -> 0 | P3: =IF(E3="",1,0) -> 0 | Q3: =IF(F3="NOT FOUND",1,0) -> 0 | R3: =IF(AND(F3<>"",F3<>"NOT FOUND",F3<>C3),1,0) -> 0 | S3: =IF(AND(M3=0,ISNUMBER(G3),N3>G3),1,0) -> 0 | T3: =IF(ABS(I3+J3-K3)>0.01,1,0) -> 0 | U3: =IFERROR(IF(ABS(J3-ROUND(I3*INDEX(Vendors!$G$2:$G$11,MATCH(C3,Vendors!$A$2:$A$11,0)),2))>0.01,1,0),0) -> 0 | V3: =IF(D3="Inactive",1,0) -> 0 | W3: =SUMIFS(Payments!$D$2:$D$69,Payments!$F$2:$F$69,A3) -> 0 | X3: =IF(AND(M3=0,W3>0,ABS(W3-K3)>0.01),1,0) -> 0 | Y3: =IF(AND(M3=0,W3=0,L3<About!$B$3),1,0) -> 0 | Z3: =M3+SUM(O3:V3)+X3+Y3 -> 0
A4: =Invoices!A4 -> INV-10164 | B4: =Invoices!B4 -> Northbridge Print Services | C4: =IFERROR(INDEX(Vendor_Aliases!$B$2:$B$25,MATCH(UPPER(TRIM(B4)),Vendor_Aliases!$A$2:$A$25,0)),"UNKNOWN") -> V001 | D4: =IFERROR(INDEX(Vendors!$E$2:$E$11,MATCH(C4,Vendors!$A$2:$A$11,0)),"") -> Active | E4: =IF(Invoices!C4="","",Invoices!C4) -> PO-4620 | F4: =IF(E4="","",IFERROR(INDEX(POs!$B$2:$B$61,MATCH(E4,POs!$A$2:$A$61,0)),"NOT FOUND")) -> V001 | G4: =IF(E4="","",IFERROR(INDEX(POs!$E$2:$E$61,MATCH(E4,POs!$A$2:$A$61,0)),"")) -> 7350 | H4: =Invoices!D4 -> 46158 | I4: =Invoices!E4 -> 6734.49 | J4: =Invoices!F4 -> 875.48 | K4: =Invoices!G4 -> 7609.97 | L4: =IFERROR(H4+INDEX(Vendors!$H$2:$H$11,MATCH(C4,Vendors!$A$2:$A$11,0)),H4+30) -> 46188 | M4: =IF(COUNTIF($A$2:A4,A4)>1,1,0) -> 0 | N4: =IF(E4="","",SUMIFS($I$2:$I$97,$E$2:$E$97,E4,$M$2:$M$97,0)) -> 6734.49 | O4: =IF(C4="UNKNOWN",1,0) -> 0 | P4: =IF(E4="",1,0) -> 0 | Q4: =IF(F4="NOT FOUND",1,0) -> 0 | R4: =IF(AND(F4<>"",F4<>"NOT FOUND",F4<>C4),1,0) -> 0 | S4: =IF(AND(M4=0,ISNUMBER(G4),N4>G4),1,0) -> 0 | T4: =IF(ABS(I4+J4-K4)>0.01,1,0) -> 0 | U4: =IFERROR(IF(ABS(J4-ROUND(I4*INDEX(Vendors!$G$2:$G$11,MATCH(C4,Vendors!$A$2:$A$11,0)),2))>0.01,1,0),0) -> 0 | V4: =IF(D4="Inactive",1,0) -> 0 | W4: =SUMIFS(Payments!$D$2:$D$69,Payments!$F$2:$F$69,A4) -> 0 | X4: =IF(AND(M4=0,W4>0,ABS(W4-K4)>0.01),1,0) -> 0 | Y4: =IF(AND(M4=0,W4=0,L4<About!$B$3),1,0) -> 1 | Z4: =M4+SUM(O4:V4)+X4+Y4 -> 1
A5: =Invoices!A5 -> INV-10158 | B5: =Invoices!B5 -> lakeshore envelope co. | C5: =IFERROR(INDEX(Vendor_Aliases!$B$2:$B$25,MATCH(UPPER(TRIM(B5)),Vendor_Aliases!$A$2:$A$25,0)),"UNKNOWN") -> V003 | D5: =IFERROR(INDEX(Vendors!$E$2:$E$11,MATCH(C5,Vendors!$A$2:$A$11,0)),"") -> Active | E5: =IF(Invoices!C5="","",Invoices!C5) -> PO-4616 | F5: =IF(E5="","",IFERROR(INDEX(POs!$B$2:$B$61,MATCH(E5,POs!$A$2:$A$61,0)),"NOT FOUND")) -> V003 | G5: =IF(E5="","",IFERROR(INDEX(POs!$E$2:$E$61,MATCH(E5,POs!$A$2:$A$61,0)),"")) -> 4850 | H5: =Invoices!D5 -> 46208 | I5: =Invoices!E5 -> 2199.23 | J5: =Invoices!F5 -> 285.9 | K5: =Invoices!G5 -> 2485.13 | L5: =IFERROR(H5+INDEX(Vendors!$H$2:$H$11,MATCH(C5,Vendors!$A$2:$A$11,0)),H5+30) -> 46253 | M5: =IF(COUNTIF($A$2:A5,A5)>1,1,0) -> 0 | N5: =IF(E5="","",SUMIFS($I$2:$I$97,$E$2:$E$97,E5,$M$2:$M$97,0)) -> 4035.8 | O5: =IF(C5="UNKNOWN",1,0) -> 0 | P5: =IF(E5="",1,0) -> 0 | Q5: =IF(F5="NOT FOUND",1,0) -> 0 | R5: =IF(AND(F5<>"",F5<>"NOT FOUND",F5<>C5),1,0) -> 0 | S5: =IF(AND(M5=0,ISNUMBER(G5),N5>G5),1,0) -> 0 | T5: =IF(ABS(I5+J5-K5)>0.01,1,0) -> 0 | U5: =IFERROR(IF(ABS(J5-ROUND(I5*INDEX(Vendors!$G$2:$G$11,MATCH(C5,Vendors!$A$2:$A$11,0)),2))>0.01,1,0),0) -> 0 | V5: =IF(D5="Inactive",1,0) -> 0 | W5: =SUMIFS(Payments!$D$2:$D$69,Payments!$F$2:$F$69,A5) -> 2485.13 | X5: =IF(AND(M5=0,W5>0,ABS(W5-K5)>0.01),1,0) -> 0 | Y5: =IF(AND(M5=0,W5=0,L5<About!$B$3),1,0) -> 0 | Z5: =M5+SUM(O5:V5)+X5+Y5 -> 0
A6: =Invoices!A6 -> INV-10079 | B6: =Invoices!B6 -> Lakeshore Envelope Co. | C6: =IFERROR(INDEX(Vendor_Aliases!$B$2:$B$25,MATCH(UPPER(TRIM(B6)),Vendor_Aliases!$A$2:$A$25,0)),"UNKNOWN") -> V003 | D6: =IFERROR(INDEX(Vendors!$E$2:$E$11,MATCH(C6,Vendors!$A$2:$A$11,0)),"") -> Active | E6: =IF(Invoices!C6="","",Invoices!C6) -> PO-4553 | F6: =IF(E6="","",IFERROR(INDEX(POs!$B$2:$B$61,MATCH(E6,POs!$A$2:$A$61,0)),"NOT FOUND")) -> V003 | G6: =IF(E6="","",IFERROR(INDEX(POs!$E$2:$E$61,MATCH(E6,POs!$A$2:$A$61,0)),"")) -> 7400 | H6: =Invoices!D6 -> 46193 | I6: =Invoices!E6 -> 7070.6 | J6: =Invoices!F6 -> 919.18 | K6: =Invoices!G6 -> 7989.78 | L6: =IFERROR(H6+INDEX(Vendors!$H$2:$H$11,MATCH(C6,Vendors!$A$2:$A$11,0)),H6+30) -> 46238 | M6: =IF(COUNTIF($A$2:A6,A6)>1,1,0) -> 0 | N6: =IF(E6="","",SUMIFS($I$2:$I$97,$E$2:$E$97,E6,$M$2:$M$97,0)) -> 7070.6 | O6: =IF(C6="UNKNOWN",1,0) -> 0 | P6: =IF(E6="",1,0) -> 0 | Q6: =IF(F6="NOT FOUND",1,0) -> 0 | R6: =IF(AND(F6<>"",F6<>"NOT FOUND",F6<>C6),1,0) -> 0 | S6: =IF(AND(M6=0,ISNUMBER(G6),N6>G6),1,0) -> 0 | T6: =IF(ABS(I6+J6-K6)>0.01,1,0) -> 0 | U6: =IFERROR(IF(ABS(J6-ROUND(I6*INDEX(Vendors!$G$2:$G$11,MATCH(C6,Vendors!$A$2:$A$11,0)),2))>0.01,1,0),0) -> 0 | V6: =IF(D6="Inactive",1,0) -> 0 | W6: =SUMIFS(Payments!$D$2:$D$69,Payments!$F$2:$F$69,A6) -> 7989.78 | X6: =IF(AND(M6=0,W6>0,ABS(W6-K6)>0.01),1,0) -> 0 | Y6: =IF(AND(M6=0,W6=0,L6<About!$B$3),1,0) -> 0 | Z6: =M6+SUM(O6:V6)+X6+Y6 -> 0
A7: =Invoices!A7 -> INV-10032 | B7: =Invoices!B7 -> MAPLE MAILING SOLUTIONS | C7: =IFERROR(INDEX(Vendor_Aliases!$B$2:$B$25,MATCH(UPPER(TRIM(B7)),Vendor_Aliases!$A$2:$A$25,0)),"UNKNOWN") -> V002 | D7: =IFERROR(INDEX(Vendors!$E$2:$E$11,MATCH(C7,Vendors!$A$2:$A$11,0)),"") -> Active | E7: =IF(Invoices!C7="","",Invoices!C7) -> PO-4520 | F7: =IF(E7="","",IFERROR(INDEX(POs!$B$2:$B$61,MATCH(E7,POs!$A$2:$A$61,0)),"NOT FOUND")) -> V002 | G7: =IF(E7="","",IFERROR(INDEX(POs!$E$2:$E$61,MATCH(E7,POs!$A$2:$A$61,0)),"")) -> 6150 | H7: =Invoices!D7 -> 46118 | I7: =Invoices!E7 -> 2372.87 | J7: =Invoices!F7 -> 308.47 | K7: =Invoices!G7 -> 2681.34 | L7: =IFERROR(H7+INDEX(Vendors!$H$2:$H$11,MATCH(C7,Vendors!$A$2:$A$11,0)),H7+30) -> 46148 | M7: =IF(COUNTIF($A$2:A7,A7)>1,1,0) -> 0 | N7: =IF(E7="","",SUMIFS($I$2:$I$97,$E$2:$E$97,E7,$M$2:$M$97,0)) -> 2372.87 | O7: =IF(C7="UNKNOWN",1,0) -> 0 | P7: =IF(E7="",1,0) -> 0 | Q7: =IF(F7="NOT FOUND",1,0) -> 0 | R7: =IF(AND(F7<>"",F7<>"NOT FOUND",F7<>C7),1,0) -> 0 | S7: =IF(AND(M7=0,ISNUMBER(G7),N7>G7),1,0) -> 0 | T7: =IF(ABS(I7+J7-K7)>0.01,1,0) -> 0 | U7: =IFERROR(IF(ABS(J7-ROUND(I7*INDEX(Vendors!$G$2:$G$11,MATCH(C7,Vendors!$A$2:$A$11,0)),2))>0.01,1,0),0) -> 0 | V7: =IF(D7="Inactive",1,0) -> 0 | W7: =SUMIFS(Payments!$D$2:$D$69,Payments!$F$2:$F$69,A7) -> 2681.34 | X7: =IF(AND(M7=0,W7>0,ABS(W7-K7)>0.01),1,0) -> 0 | Y7: =IF(AND(M7=0,W7=0,L7<About!$B$3),1,0) -> 0 | Z7: =M7+SUM(O7:V7)+X7+Y7 -> 0
A8: =Invoices!A8 -> INV-10111 | B8: =Invoices!B8 -> Maple Mailing Solutions | C8: =IFERROR(INDEX(Vendor_Aliases!$B$2:$B$25,MATCH(UPPER(TRIM(B8)),Vendor_Aliases!$A$2:$A$25,0)),"UNKNOWN") -> V002 | D8: =IFERROR(INDEX(Vendors!$E$2:$E$11,MATCH(C8,Vendors!$A$2:$A$11,0)),"") -> Active | E8: =IF(Invoices!C8="","",Invoices!C8) -> PO-4582 | F8: =IF(E8="","",IFERROR(INDEX(POs!$B$2:$B$61,MATCH(E8,POs!$A$2:$A$61,0)),"NOT FOUND")) -> V002 | G8: =IF(E8="","",IFERROR(INDEX(POs!$E$2:$E$61,MATCH(E8,POs!$A$2:$A$61,0)),"")) -> 14300 | H8: =Invoices!D8 -> 46090 | I8: =Invoices!E8 -> 13086 | J8: =Invoices!F8 -> 1701.18 | K8: =Invoices!G8 -> 14787.18 | L8: =IFERROR(H8+INDEX(Vendors!$H$2:$H$11,MATCH(C8,Vendors!$A$2:$A$11,0)),H8+30) -> 46120 | M8: =IF(COUNTIF($A$2:A8,A8)>1,1,0) -> 0 | N8: =IF(E8="","",SUMIFS($I$2:$I$97,$E$2:$E$97,E8,$M$2:$M$97,0)) -> 13086 | O8: =IF(C8="UNKNOWN",1,0) -> 0 | P8: =IF(E8="",1,0) -> 0 | Q8: =IF(F8="NOT FOUND",1,0) -> 0 | R8: =IF(AND(F8<>"",F8<>"NOT FOUND",F8<>C8),1,0) -> 0 | S8: =IF(AND(M8=0,ISNUMBER(G8),N8>G8),1,0) -> 0 | T8: =IF(ABS(I8+J8-K8)>0.01,1,0) -> 0 | U8: =IFERROR(IF(ABS(J8-ROUND(I8*INDEX(Vendors!$G$2:$G$11,MATCH(C8,Vendors!$A$2:$A$11,0)),2))>0.01,1,0),0) -> 0 | V8: =IF(D8="Inactive",1,0) -> 0 | W8: =SUMIFS(Payments!$D$2:$D$69,Payments!$F$2:$F$69,A8) -> 0 | X8: =IF(AND(M8=0,W8>0,ABS(W8-K8)>0.01),1,0) -> 0 | Y8: =IF(AND(M8=0,W8=0,L8<About!$B$3),1,0) -> 1 | Z8: =M8+SUM(O8:V8)+X8+Y8 -> 1
A9: =Invoices!A9 -> INV-10077 | B9: =Invoices!B9 -> Maple Mailing Solutions | C9: =IFERROR(INDEX(Vendor_Aliases!$B$2:$B$25,MATCH(UPPER(TRIM(B9)),Vendor_Aliases!$A$2:$A$25,0)),"UNKNOWN") -> V002 | D9: =IFERROR(INDEX(Vendors!$E$2:$E$11,MATCH(C9,Vendors!$A$2:$A$11,0)),"") -> Active | E9: =IF(Invoices!C9="","",Invoices!C9) -> PO-4550 | F9: =IF(E9="","",IFERROR(INDEX(POs!$B$2:$B$61,MATCH(E9,POs!$A$2:$A$61,0)),"NOT FOUND")) -> V002 | G9: =IF(E9="","",IFERROR(INDEX(POs!$E$2:$E$61,MATCH(E9,POs!$A$2:$A$61,0)),"")) -> 5250 | H9: =Invoices!D9 -> 46240 | I9: =Invoices!E9 -> 4742.08 | J9: =Invoices!F9 -> 616.47 | K9: =Invoices!G9 -> 5358.55 | L9: =IFERROR(H9+INDEX(Vendors!$H$2:$H$11,MATCH(C9,Vendors!$A$2:$A$11,0)),H9+30) -> 46270 | M9: =IF(COUNTIF($A$2:A9,A9)>1,1,0) -> 0 | N9: =IF(E9="","",SUMIFS($I$2:$I$97,$E$2:$E$97,E9,$M$2:$M$97,0)) -> 4742.08 | O9: =IF(C9="UNKNOWN",1,0) -> 0 | P9: =IF(E9="",1,0) -> 0 | Q9: =IF(F9="NOT FOUND",1,0) -> 0 | R9: =IF(AND(F9<>"",F9<>"NOT FOUND",F9<>C9),1,0) -> 0 | S9: =IF(AND(M9=0,ISNUMBER(G9),N9>G9),1,0) -> 0 | T9: =IF(ABS(I9+J9-K9)>0.01,1,0) -> 0 | U9: =IFERROR(IF(ABS(J9-ROUND(I9*INDEX(Vendors!$G$2:$G$11,MATCH(C9,Vendors!$A$2:$A$11,0)),2))>0.01,1,0),0) -> 0 | V9: =IF(D9="Inactive",1,0) -> 0 | W9: =SUMIFS(Payments!$D$2:$D$69,Payments!$F$2:$F$69,A9) -> 5358.55 | X9: =IF(AND(M9=0,W9>0,ABS(W9-K9)>0.01),1,0) -> 0 | Y9: =IF(AND(M9=0,W9=0,L9<About!$B$3),1,0) -> 0 | Z9: =M9+SUM(O9:V9)+X9+Y9 -> 0
A10: =Invoices!A10 -> INV-10056 | B10: =Invoices!B10 -> CLEARPATH FULFILMENT | C10: =IFERROR(INDEX(Vendor_Aliases!$B$2:$B$25,MATCH(UPPER(TRIM(B10)),Vendor_Aliases!$A$2:$A$25,0)),"UNKNOWN") -> V008 | D10: =IFERROR(INDEX(Vendors!$E$2:$E$11,MATCH(C10,Vendors!$A$2:$A$11,0)),"") -> Active | E10: =IF(Invoices!C10="","",Invoices!C10) -> PO-4537 | F10: =IF(E10="","",IFERROR(INDEX(POs!$B$2:$B$61,MATCH(E10,POs!$A$2:$A$61,0)),"NOT FOUND")) -> V008 | G10: =IF(E10="","",IFERROR(INDEX(POs!$E$2:$E$61,MATCH(E10,POs!$A$2:$A$61,0)),"")) -> 15500 | H10: =Invoices!D10 -> 46158 | I10: =Invoices!E10 -> 6017.78 | J10: =Invoices!F10 -> 782.31 | K10: =Invoices!G10 -> 6800.09 | L10: =IFERROR(H10+INDEX(Vendors!$H$2:$H$11,MATCH(C10,Vendors!$A$2:$A$11,0)),H10+30) -> 46188 | M10: =IF(COUNTIF($A$2:A10,A10)>1,1,0) -> 0 | N10: =IF(E10="","",SUMIFS($I$2:$I$97,$E$2:$E$97,E10,$M$2:$M$97,0)) -> 13089.1 | O10: =IF(C10="UNKNOWN",1,0) -> 0 | P10: =IF(E10="",1,0) -> 0 | Q10: =IF(F10="NOT FOUND",1,0) -> 0 | R10: =IF(AND(F10<>"",F10<>"NOT FOUND",F10<>C10),1,0) -> 0 | S10: =IF(AND(M10=0,ISNUMBER(G10),N10>G10),1,0) -> 0 | T10: =IF(ABS(I10+J10-K10)>0.01,1,0) -> 0 | U10: =IFERROR(IF(ABS(J10-ROUND(I10*INDEX(Vendors!$G$2:$G$11,MATCH(C10,Vendors!$A$2:$A$11,0)),2))>0.01,1,0),0) -> 0 | V10: =IF(D10="Inactive",1,0) -> 0 | W10: =SUMIFS(Payments!$D$2:$D$69,Payments!$F$2:$F$69,A10) -> 6800.09 | X10: =IF(AND(M10=0,W10>0,ABS(W10-K10)>0.01),1,0) -> 0 | Y10: =IF(AND(M10=0,W10=0,L10<About!$B$3),1,0) -> 0 | Z10: =M10+SUM(O10:V10)+X10+Y10 -> 0
A11: =Invoices!A11 -> INV-10070 | B11: =Invoices!B11 -> lakeshore envelope co. | C11: =IFERROR(INDEX(Vendor_Aliases!$B$2:$B$25,MATCH(UPPER(TRIM(B11)),Vendor_Aliases!$A$2:$A$25,0)),"UNKNOWN") -> V003 | D11: =IFERROR(INDEX(Vendors!$E$2:$E$11,MATCH(C11,Vendors!$A$2:$A$11,0)),"") -> Active | E11: =IF(Invoices!C11="","",Invoices!C11) -> PO-4543 | F11: =IF(E11="","",IFERROR(INDEX(POs!$B$2:$B$61,MATCH(E11,POs!$A$2:$A$61,0)),"NOT FOUND")) -> V003 | G11: =IF(E11="","",IFERROR(INDEX(POs!$E$2:$E$61,MATCH(E11,POs!$A$2:$A$61,0)),"")) -> 2450 | H11: =Invoices!D11 -> 46188 | I11: =Invoices!E11 -> 1121.16 | J11: =Invoices!F11 -> 145.75 | K11: =Invoices!G11 -> 1266.91 | L11: =IFERROR(H11+INDEX(Vendors!$H$2:$H$11,MATCH(C11,Vendors!$A$2:$A$11,0)),H11+30) -> 46233 | M11: =IF(COUNTIF($A$2:A11,A11)>1,1,0) -> 0 | N11: =IF(E11="","",SUMIFS($I$2:$I$97,$E$2:$E$97,E11,$M$2:$M$97,0)) -> 2068.43 | O11: =IF(C11="UNKNOWN",1,0) -> 0 | P11: =IF(E11="",1,0) -> 0 | Q11: =IF(F11="NOT FOUND",1,0) -> 0 | R11: =IF(AND(F11<>"",F11<>"NOT FOUND",F11<>C11),1,0) -> 0 | S11: =IF(AND(M11=0,ISNUMBER(G11),N11>G11),1,0) -> 0 | T11: =IF(ABS(I11+J11-K11)>0.01,1,0) -> 0 | U11: =IFERROR(IF(ABS(J11-ROUND(I11*INDEX(Vendors!$G$2:$G$11,MATCH(C11,Vendors!$A$2:$A$11,0)),2))>0.01,1,0),0) -> 0 | V11: =IF(D11="Inactive",1,0) -> 0 | W11: =SUMIFS(Payments!$D$2:$D$69,Payments!$F$2:$F$69,A11) -> 1266.91 | X11: =IF(AND(M11=0,W11>0,ABS(W11-K11)>0.01),1,0) -> 0 | Y11: =IF(AND(M11=0,W11=0,L11<About!$B$3),1,0) -> 0 | Z11: =M11+SUM(O11:V11)+X11+Y11 -> 0
A12: =Invoices!A12 -> INV-10028 | B12: =Invoices!B12 -> Summit Digital Print Inc. | C12: =IFERROR(INDEX(Vendor_Aliases!$B$2:$B$25,MATCH(UPPER(TRIM(B12)),Vendor_Aliases!$A$2:$A$25,0)),"UNKNOWN") -> V004 | D12: =IFERROR(INDEX(Vendors!$E$2:$E$11,MATCH(C12,Vendors!$A$2:$A$11,0)),"") -> Active | E12: =IF(Invoices!C12="","",Invoices!C12) -> PO-4516 | F12: =IF(E12="","",IFERROR(INDEX(POs!$B$2:$B$61,MATCH(E12,POs!$A$2:$A$61,0)),"NOT FOUND")) -> V004 | G12: =IF(E12="","",IFERROR(INDEX(POs!$E$2:$E$61,MATCH(E12,POs!$A$2:$A$61,0)),"")) -> 4000 | H12: =Invoices!D12 -> 46048 | I12: =Invoices!E12 -> 3495.03 | J12: =Invoices!F12 -> 523.38 | K12: =Invoices!G12 -> 4018.41 | L12: =IFERROR(H12+INDEX(Vendors!$H$2:$H$11,MATCH(C12,Vendors!$A$2:$A$11,0)),H12+30) -> 46078 | M12: =IF(COUNTIF($A$2:A12,A12)>1,1,0) -> 0 | N12: =IF(E12="","",SUMIFS($I$2:$I$97,$E$2:$E$97,E12,$M$2:$M$97,0)) -> 3495.03 | O12: =IF(C12="UNKNOWN",1,0) -> 0 | P12: =IF(E12="",1,0) -> 0 | Q12: =IF(F12="NOT FOUND",1,0) -> 0 | R12: =IF(AND(F12<>"",F12<>"NOT FOUND",F12<>C12),1,0) -> 0 | S12: =IF(AND(M12=0,ISNUMBER(G12),N12>G12),1,0) -> 0 | T12: =IF(ABS(I12+J12-K12)>0.01,1,0) -> 0 | U12: =IFERROR(IF(ABS(J12-ROUND(I12*INDEX(Vendors!$G$2:$G$11,MATCH(C12,Vendors!$A$2:$A$11,0)),2))>0.01,1,0),0) -> 0 | V12: =IF(D12="Inactive",1,0) -> 0 | W12: =SUMIFS(Payments!$D$2:$D$69,Payments!$F$2:$F$69,A12) -> 4018.41 | X12: =IF(AND(M12=0,W12>0,ABS(W12-K12)>0.01),1,0) -> 0 | Y12: =IF(AND(M12=0,W12=0,L12<About!$B$3),1,0) -> 0 | Z12: =M12+SUM(O12:V12)+X12+Y12 -> 0
A13: =Invoices!A13 -> INV-10046 | B13: =Invoices!B13 -> ClearPath Fulfillment | C13: =IFERROR(INDEX(Vendor_Aliases!$B$2:$B$25,MATCH(UPPER(TRIM(B13)),Vendor_Aliases!$A$2:$A$25,0)),"UNKNOWN") -> V008 | D13: =IFERROR(INDEX(Vendors!$E$2:$E$11,MATCH(C13,Vendors!$A$2:$A$11,0)),"") -> Active | E13: =IF(Invoices!C13="","",Invoices!C13) -> PO-4531 | F13: =IF(E13="","",IFERROR(INDEX(POs!$B$2:$B$61,MATCH(E13,POs!$A$2:$A$61,0)),"NOT FOUND")) -> V008 | G13: =IF(E13="","",IFERROR(INDEX(POs!$E$2:$E$61,MATCH(E13,POs!$A$2:$A$61,0)),"")) -> 8300 | H13: =Invoices!D13 -> 46075 | I13: =Invoices!E13 -> 7344.57 | J13: =Invoices!F13 -> 954.79 | K13: =Invoices!G13 -> 8299.36 | L13: =IFERROR(H13+INDEX(Vendors!$H$2:$H$11,MATCH(C13,Vendors!$A$2:$A$11,0)),H13+30) -> 46105 | M13: =IF(COUNTIF($A$2:A13,A13)>1,1,0) -> 0 | N13: =IF(E13="","",SUMIFS($I$2:$I$97,$E$2:$E$97,E13,$M$2:$M$97,0)) -> 7344.57 | O13: =IF(C13="UNKNOWN",1,0) -> 0 | P13: =IF(E13="",1,0) -> 0 | Q13: =IF(F13="NOT FOUND",1,0) -> 0 | R13: =IF(AND(F13<>"",F13<>"NOT FOUND",F13<>C13),1,0) -> 0 | S13: =IF(AND(M13=0,ISNUMBER(G13),N13>G13),1,0) -> 0 | T13: =IF(ABS(I13+J13-K13)>0.01,1,0) -> 0 | U13: =IFERROR(IF(ABS(J13-ROUND(I13*INDEX(Vendors!$G$2:$G$11,MATCH(C13,Vendors!$A$2:$A$11,0)),2))>0.01,1,0),0) -> 0 | V13: =IF(D13="Inactive",1,0) -> 0 | W13: =SUMIFS(Payments!$D$2:$D$69,Payments!$F$2:$F$69,A13) -> 8299.36 | X13: =IF(AND(M13=0,W13>0,ABS(W13-K13)>0.01),1,0) -> 0 | Y13: =IF(AND(M13=0,W13=0,L13<About!$B$3),1,0) -> 0 | Z13: =M13+SUM(O13:V13)+X13+Y13 -> 0
... A97: =Invoices!A97 -> INV-10104 | B97: =Invoices!B97 -> CEDARLINE PAPER SUPPLY | C97: =IFERROR(INDEX(Vendor_Aliases!$B$2:$B$25,MATCH(UPPER(TRIM(B97)),Vendor_Aliases!$A$2:$A$25,0)),"UNKNOWN") -> V006 | D97: =IFERROR(INDEX(Vendors!$E$2:$E$11,MATCH(C97,Vendors!$A$2:$A$11,0)),"") -> Active | E97: =IF(Invoices!C97="","",Invoices!C97) -> PO-4571 | F97: =IF(E97="","",IFERROR(INDEX(POs!$B$2:$B$61,MATCH(E97,POs!$A$2:$A$61,0)),"NOT FOUND")) -> V006 | G97: =IF(E97="","",IFERROR(INDEX(POs!$E$2:$E$61,MATCH(E97,POs!$A$2:$A$61,0)),"")) -> 19200 | H97: =Invoices!D97 -> 46167 | I97: =Invoices!E97 -> 9984 | J97: =Invoices!F97 -> 1297.92 | K97: =Invoices!G97 -> 11281.92 | L97: =IFERROR(H97+INDEX(Vendors!$H$2:$H$11,MATCH(C97,Vendors!$A$2:$A$11,0)),H97+30) -> 46212 | M97: =IF(COUNTIF($A$2:A97,A97)>1,1,0) -> 0 | N97: =IF(E97="","",SUMIFS($I$2:$I$97,$E$2:$E$97,E97,$M$2:$M$97,0)) -> 22464 | O97: =IF(C97="UNKNOWN",1,0) -> 0 | P97: =IF(E97="",1,0) -> 0 | Q97: =IF(F97="NOT FOUND",1,0) -> 0 | R97: =IF(AND(F97<>"",F97<>"NOT FOUND",F97<>C97),1,0) -> 0 | S97: =IF(AND(M97=0,ISNUMBER(G97),N97>G97),1,0) -> 1 | T97: =IF(ABS(I97+J97-K97)>0.01,1,0) -> 0 | U97: =IFERROR(IF(ABS(J97-ROUND(I97*INDEX(Vendors!$G$2:$G$11,MATCH(C97,Vendors!$A$2:$A$11,0)),2))>0.01,1,0),0) -> 0 | V97: =IF(D97="Inactive",1,0) -> 0 | W97: =SUMIFS(Payments!$D$2:$D$69,Payments!$F$2:$F$69,A97) -> 0 | X97: =IF(AND(M97=0,W97>0,ABS(W97-K97)>0.01),1,0) -> 0 | Y97: =IF(AND(M97=0,W97=0,L97<About!$B$3),1,0) -> 1 | Z97: =M97+SUM(O97:V97)+X97+Y97 -> 2

Sheet Payment_Checks
A1: PaymentRef | B1: InvoiceNo_Key | C1: PaidAmount | D1: Matched_Invoice | E1: Flag_OrphanPayment
A2: =Payments!A2 -> EFT880075 | B2: =Payments!F2 -> INV-10036 | C2: =Payments!D2 -> 7662.95 | D2: =IF(COUNTIF(Invoices!$A$2:$A$97,B2)>0,"Yes","No") -> Yes | E2: =IF(D2="No",1,0) -> 0
A3: =Payments!A3 -> EFT880312 | B3: =Payments!F3 -> INV-10145 | C3: =Payments!D3 -> 11363.34 | D3: =IF(COUNTIF(Invoices!$A$2:$A$97,B3)>0,"Yes","No") -> Yes | E3: =IF(D3="No",1,0) -> 0
A4: =Payments!A4 -> EFT880220 | B4: =Payments!F4 -> INV-10071 | C4: =Payments!D4 -> 1070.42 | D4: =IF(COUNTIF(Invoices!$A$2:$A$97,B4)>0,"Yes","No") -> Yes | E4: =IF(D4="No",1,0) -> 0
A5: =Payments!A5 -> EFT880139 | B5: =Payments!F5 -> INV-10067 | C5: =Payments!D5 -> 2346.66 | D5: =IF(COUNTIF(Invoices!$A$2:$A$97,B5)>0,"Yes","No") -> Yes | E5: =IF(D5="No",1,0) -> 0
A6: =Payments!A6 -> EFT880063 | B6: =Payments!F6 -> INV-10087 | C6: =Payments!D6 -> 2010.22 | D6: =IF(COUNTIF(Invoices!$A$2:$A$97,B6)>0,"Yes","No") -> Yes | E6: =IF(D6="No",1,0) -> 0
A7: =Payments!A7 -> EFT880037 | B7: =Payments!F7 -> INV-10070 | C7: =Payments!D7 -> 1266.91 | D7: =IF(COUNTIF(Invoices!$A$2:$A$97,B7)>0,"Yes","No") -> Yes | E7: =IF(D7="No",1,0) -> 0
A8: =Payments!A8 -> EFT880206 | B8: =Payments!F8 -> INV-10010 | C8: =Payments!D8 -> 4414.68 | D8: =IF(COUNTIF(Invoices!$A$2:$A$97,B8)>0,"Yes","No") -> Yes | E8: =IF(D8="No",1,0) -> 0
A9: =Payments!A9 -> EFT880043 | B9: =Payments!F9 -> INV-10046 | C9: =Payments!D9 -> 8299.36 | D9: =IF(COUNTIF(Invoices!$A$2:$A$97,B9)>0,"Yes","No") -> Yes | E9: =IF(D9="No",1,0) -> 0
A10: =Payments!A10 -> EFT880317 | B10: =Payments!F10 -> INV-99001 | C10: =Payments!D10 -> 1005.11 | D10: =IF(COUNTIF(Invoices!$A$2:$A$97,B10)>0,"Yes","No") -> No | E10: =IF(D10="No",1,0) -> 1
A11: =Payments!A11 -> EFT880026 | B11: =Payments!F11 -> INV-10077 | C11: =Payments!D11 -> 5358.55 | D11: =IF(COUNTIF(Invoices!$A$2:$A$97,B11)>0,"Yes","No") -> Yes | E11: =IF(D11="No",1,0) -> 0
A12: =Payments!A12 -> EFT880190 | B12: =Payments!F12 -> INV-10159 | C12: =Payments!D12 -> 2075.32 | D12: =IF(COUNTIF(Invoices!$A$2:$A$97,B12)>0,"Yes","No") -> Yes | E12: =IF(D12="No",1,0) -> 0
A13: =Payments!A13 -> EFT880070 | B13: =Payments!F13 -> INV-10023 | C13: =Payments!D13 -> 1821.56 | D13: =IF(COUNTIF(Invoices!$A$2:$A$97,B13)>0,"Yes","No") -> Yes | E13: =IF(D13="No",1,0) -> 0
... A69: =Payments!A69 -> EFT880136 | B69: =Payments!F69 -> INV-10043 | C69: =Payments!D69 -> 3731.7 | D69: =IF(COUNTIF(Invoices!$A$2:$A$97,B69)>0,"Yes","No") -> Yes | E69: =IF(D69="No",1,0) -> 0

Sheet Mapping_Checks
A1: Application | B1: DocumentType | C1: PrintVendorID | D1: MailVendorID | E1: Owner | F1: Flag_MissingMailVendor | G1: Flag_MissingOwner | H1: Flag_InactiveVendorMapped
A2: Individual Insurance | B2: Tax Slip (T4A/T5) | C2: V001 | E2: Vendor Governance | F2: =IF(D2="",1,0) -> 1 | G2: =IF(E2="",1,0) -> 0 | H2: =IF(OR(IFERROR(INDEX(Vendors!$E$2:$E$11,MATCH(C2,Vendors!$A$2:$A$11,0)),"")="Inactive",IFERROR(INDEX(Vendors!$E$2:$E$11,MATCH(D2,Vendors!$A$2:$A$11,0)),"")="Inactive"),1,0) -> 0
A3: Individual Insurance | B3: Renewal Notice | C3: V004 | D3: V010 | E3: Production Ops | F3: =IF(D3="",1,0) -> 0 | G3: =IF(E3="",1,0) -> 0 | H3: =IF(OR(IFERROR(INDEX(Vendors!$E$2:$E$11,MATCH(C3,Vendors!$A$2:$A$11,0)),"")="Inactive",IFERROR(INDEX(Vendors!$E$2:$E$11,MATCH(D3,Vendors!$A$2:$A$11,0)),"")="Inactive"),1,0) -> 1
A4: Individual Insurance | B4: Welcome Kit | C4: V004 | D4: V010 | E4: Vendor Governance | F4: =IF(D4="",1,0) -> 0 | G4: =IF(E4="",1,0) -> 0 | H4: =IF(OR(IFERROR(INDEX(Vendors!$E$2:$E$11,MATCH(C4,Vendors!$A$2:$A$11,0)),"")="Inactive",IFERROR(INDEX(Vendors!$E$2:$E$11,MATCH(D4,Vendors!$A$2:$A$11,0)),"")="Inactive"),1,0) -> 1
A5: Group Benefits | B5: Tax Slip (T4A/T5) | C5: V001 | D5: V010 | F5: =IF(D5="",1,0) -> 0 | G5: =IF(E5="",1,0) -> 1 | H5: =IF(OR(IFERROR(INDEX(Vendors!$E$2:$E$11,MATCH(C5,Vendors!$A$2:$A$11,0)),"")="Inactive",IFERROR(INDEX(Vendors!$E$2:$E$11,MATCH(D5,Vendors!$A$2:$A$11,0)),"")="Inactive"),1,0) -> 1
A6: Group Benefits | B6: Renewal Notice | C6: V009 | D6: V002 | F6: =IF(D6="",1,0) -> 0 | G6: =IF(E6="",1,0) -> 1 | H6: =IF(OR(IFERROR(INDEX(Vendors!$E$2:$E$11,MATCH(C6,Vendors!$A$2:$A$11,0)),"")="Inactive",IFERROR(INDEX(Vendors!$E$2:$E$11,MATCH(D6,Vendors!$A$2:$A$11,0)),"")="Inactive"),1,0) -> 0
A7: Group Retirement | B7: Renewal Notice | C7: V007 | D7: V010 | E7: Production Ops | F7: =IF(D7="",1,0) -> 0 | G7: =IF(E7="",1,0) -> 0 | H7: =IF(OR(IFERROR(INDEX(Vendors!$E$2:$E$11,MATCH(C7,Vendors!$A$2:$A$11,0)),"")="Inactive",IFERROR(INDEX(Vendors!$E$2:$E$11,MATCH(D7,Vendors!$A$2:$A$11,0)),"")="Inactive"),1,0) -> 1
A8: Group Retirement | B8: Welcome Kit | C8: V004 | D8: V002 | E8: Vendor Governance | F8: =IF(D8="",1,0) -> 0 | G8: =IF(E8="",1,0) -> 0 | H8: =IF(OR(IFERROR(INDEX(Vendors!$E$2:$E$11,MATCH(C8,Vendors!$A$2:$A$11,0)),"")="Inactive",IFERROR(INDEX(Vendors!$E$2:$E$11,MATCH(D8,Vendors!$A$2:$A$11,0)),"")="Inactive"),1,0) -> 0
A9: Wealth & Asset Mgmt | B9: Policy Package | C9: V004 | D9: V002 | E9: Production Ops | F9: =IF(D9="",1,0) -> 0 | G9: =IF(E9="",1,0) -> 0 | H9: =IF(OR(IFERROR(INDEX(Vendors!$E$2:$E$11,MATCH(C9,Vendors!$A$2:$A$11,0)),"")="Inactive",IFERROR(INDEX(Vendors!$E$2:$E$11,MATCH(D9,Vendors!$A$2:$A$11,0)),"")="Inactive"),1,0) -> 0
A10: Wealth & Asset Mgmt | B10: Tax Slip (T4A/T5) | C10: V001 | D10: V002 | F10: =IF(D10="",1,0) -> 0 | G10: =IF(E10="",1,0) -> 1 | H10: =IF(OR(IFERROR(INDEX(Vendors!$E$2:$E$11,MATCH(C10,Vendors!$A$2:$A$11,0)),"")="Inactive",IFERROR(INDEX(Vendors!$E$2:$E$11,MATCH(D10,Vendors!$A$2:$A$11,0)),"")="Inactive"),1,0) -> 0
A11: Wealth & Asset Mgmt | B11: Renewal Notice | C11: V004 | E11: Production Ops | F11: =IF(D11="",1,0) -> 1 | G11: =IF(E11="",1,0) -> 0 | H11: =IF(OR(IFERROR(INDEX(Vendors!$E$2:$E$11,MATCH(C11,Vendors!$A$2:$A$11,0)),"")="Inactive",IFERROR(INDEX(Vendors!$E$2:$E$11,MATCH(D11,Vendors!$A$2:$A$11,0)),"")="Inactive"),1,0) -> 0
A12: Wealth & Asset Mgmt | B12: Welcome Kit | C12: V004 | E12: Production Ops | F12: =IF(D12="",1,0) -> 1 | G12: =IF(E12="",1,0) -> 0 | H12: =IF(OR(IFERROR(INDEX(Vendors!$E$2:$E$11,MATCH(C12,Vendors!$A$2:$A$11,0)),"")="Inactive",IFERROR(INDEX(Vendors!$E$2:$E$11,MATCH(D12,Vendors!$A$2:$A$11,0)),"")="Inactive"),1,0) -> 0
A13: Banking | B13: Annual Statement | C13: V004 | F13: =IF(D13="",1,0) -> 1 | G13: =IF(E13="",1,0) -> 1 | H13: =IF(OR(IFERROR(INDEX(Vendors!$E$2:$E$11,MATCH(C13,Vendors!$A$2:$A$11,0)),"")="Inactive",IFERROR(INDEX(Vendors!$E$2:$E$11,MATCH(D13,Vendors!$A$2:$A$11,0)),"")="Inactive"),1,0) -> 0
A14: Banking | B14: Policy Package | C14: V007 | D14: V002 | F14: =IF(D14="",1,0) -> 0 | G14: =IF(E14="",1,0) -> 1 | H14: =IF(OR(IFERROR(INDEX(Vendors!$E$2:$E$11,MATCH(C14,Vendors!$A$2:$A$11,0)),"")="Inactive",IFERROR(INDEX(Vendors!$E$2:$E$11,MATCH(D14,Vendors!$A$2:$A$11,0)),"")="Inactive"),1,0) -> 1
A15: Banking | B15: Tax Slip (T4A/T5) | C15: V007 | D15: V002 | E15: Vendor Governance | F15: =IF(D15="",1,0) -> 0 | G15: =IF(E15="",1,0) -> 0 | H15: =IF(OR(IFERROR(INDEX(Vendors!$E$2:$E$11,MATCH(C15,Vendors!$A$2:$A$11,0)),"")="Inactive",IFERROR(INDEX(Vendors!$E$2:$E$11,MATCH(D15,Vendors!$A$2:$A$11,0)),"")="Inactive"),1,0) -> 1
A16: Banking | B16: Welcome Kit | C16: V007 | E16: Vendor Governance | F16: =IF(D16="",1,0) -> 1 | G16: =IF(E16="",1,0) -> 0 | H16: =IF(OR(IFERROR(INDEX(Vendors!$E$2:$E$11,MATCH(C16,Vendors!$A$2:$A$11,0)),"")="Inactive",IFERROR(INDEX(Vendors!$E$2:$E$11,MATCH(D16,Vendors!$A$2:$A$11,0)),"")="Inactive"),1,0) -> 1

Sheet Issues_Summary
A1: Issue | B1: Invoices / rows | C1: Dollar value at stake | D1: Suggested action
A2: Duplicate invoice (same InvoiceNo entered twice) | B2: =SUM(Checks!$M$2:$M$97) -> 4 | C2: =SUMIFS(Checks!$K$2:$K$97,Checks!$M$2:$M$97,1) -> 37619.05 | D2: Hold payment on the duplicate; ask AP to void it.
A3: Vendor name not in vendor master | B3: =SUM(Checks!$O$2:$O$97) -> 2 | C3: =SUMIFS(Checks!$K$2:$K$97,Checks!$O$2:$O$97,1) -> 11458.35 | D3: Confirm with Vendor Governance whether to onboard or reject.
A4: Invoice has no PO number | B4: =SUM(Checks!$P$2:$P$97) -> 8 | C4: =SUMIFS(Checks!$K$2:$K$97,Checks!$P$2:$P$97,1) -> 38730.8 | D4: Ask requester for the PO; no PO = no payment approval.
A5: PO number not found in PO system | B5: =SUM(Checks!$Q$2:$Q$97) -> 0 | C5: =SUMIFS(Checks!$K$2:$K$97,Checks!$Q$2:$Q$97,1) -> 0 | D5: Check for typo or PO raised in another system.
A6: Invoice vendor differs from PO vendor | B6: =SUM(Checks!$R$2:$R$97) -> 0 | C6: =SUMIFS(Checks!$K$2:$K$97,Checks!$R$2:$R$97,1) -> 0 | D6: Possible mis-keyed PO; confirm with requester.
A7: Cumulative invoices exceed PO approved amount | B7: =SUM(Checks!$S$2:$S$97) -> 5 | C7: =SUMIFS(Checks!$K$2:$K$97,Checks!$S$2:$S$97,1) -> 52844 | D7: Needs PO amendment or approver sign-off.
A8: Net + Tax does not equal Invoice Total | B8: =SUM(Checks!$T$2:$T$97) -> 5 | C8: =SUMIFS(Checks!$K$2:$K$97,Checks!$T$2:$T$97,1) -> 26104.18 | D8: Request corrected invoice from vendor.
A9: Tax not at expected provincial rate | B9: =SUM(Checks!$U$2:$U$97) -> 0 | C9: =SUMIFS(Checks!$J$2:$J$97,Checks!$U$2:$U$97,1) -> 0 | D9: Check vendor's tax registration / place of supply.
A10: Invoice from vendor marked Inactive | B10: =SUM(Checks!$V$2:$V$97) -> 8 | C10: =SUMIFS(Checks!$K$2:$K$97,Checks!$V$2:$V$97,1) -> 41793.23 | D10: Confirm whether vendor should be reactivated.
A11: Paid amount differs from invoice total | B11: =SUM(Checks!$X$2:$X$97) -> 2 | C11: =SUMIFS(Checks!$W$2:$W$97,Checks!$X$2:$X$97,1) -> 10872.78 | D11: Short/over payment; reconcile with Treasury.
A12: Unpaid and past due as of as-of date | B12: =SUM(Checks!$Y$2:$Y$97) -> 20 | C12: =SUMIFS(Checks!$K$2:$K$97,Checks!$Y$2:$Y$97,1) -> 172409.58 | D12: Escalate to AP for payment run.
A13: Payment with no matching invoice (orphan) | B13: =SUM(Payment_Checks!$E$2:$E$69) -> 2 | C13: =SUMIFS(Payment_Checks!$C$2:$C$69,Payment_Checks!$E$2:$E$69,1) -> 2017.55 | D13: Trace with Treasury; possible misapplied payment.
A14: Mapping row missing mail vendor | B14: =SUM(Mapping_Checks!$F$2:$F$16) -> 5 | C14: n/a | D14: Fill in with Production Ops.
A15: Mapping row missing owner | B15: =SUM(Mapping_Checks!$G$2:$G$16) -> 5 | C15: n/a | D15: Assign an owner team.
A16: Mapping row uses an Inactive vendor | B16: =SUM(Mapping_Checks!$H$2:$H$16) -> 7 | C16: n/a | D16: Re-map to an active vendor.
A18: Invoices with at least one issue | B18: =COUNTIF(Checks!$Z$2:$Z$97,">0") -> 42
A19: Total invoice rows | B19: =COUNTA(Checks!$A$2:$A$97) -> 96
A21: Dollar value = invoice total of flagged rows, except tax rows (tax amount) and payment rows (amount paid).

Sheet Vendor_Summary
A1: VendorID | B1: VendorName | C1: Status | D1: Invoices (excl. dup) | E1: Invoiced Total | F1: Paid | G1: Outstanding | H1: Invoices with issues
A2: V001 | B2: =IFERROR(INDEX(Vendors!$B$2:$B$11,MATCH(A2,Vendors!$A$2:$A$11,0)),"Not in vendor master") -> Northbridge Print Services | C2: =IFERROR(INDEX(Vendors!$E$2:$E$11,MATCH(A2,Vendors!$A$2:$A$11,0)),"") -> Active | D2: =COUNTIFS(Checks!$C$2:$C$97,A2,Checks!$M$2:$M$97,0) -> 9 | E2: =SUMIFS(Checks!$K$2:$K$97,Checks!$C$2:$C$97,A2,Checks!$M$2:$M$97,0) -> 44714.29 | F2: =SUMIFS(Checks!$W$2:$W$97,Checks!$C$2:$C$97,A2,Checks!$M$2:$M$97,0) -> 29702.81 | G2: =E2-F2 -> 15011.48 | H2: =COUNTIFS(Checks!$C$2:$C$97,A2,Checks!$Z$2:$Z$97,">0") -> 3
A3: V002 | B3: =IFERROR(INDEX(Vendors!$B$2:$B$11,MATCH(A3,Vendors!$A$2:$A$11,0)),"Not in vendor master") -> Maple Mailing Solutions | C3: =IFERROR(INDEX(Vendors!$E$2:$E$11,MATCH(A3,Vendors!$A$2:$A$11,0)),"") -> Active | D3: =COUNTIFS(Checks!$C$2:$C$97,A3,Checks!$M$2:$M$97,0) -> 19 | E3: =SUMIFS(Checks!$K$2:$K$97,Checks!$C$2:$C$97,A3,Checks!$M$2:$M$97,0) -> 136419.67 | F3: =SUMIFS(Checks!$W$2:$W$97,Checks!$C$2:$C$97,A3,Checks!$M$2:$M$97,0) -> 75045.4 | G3: =E3-F3 -> 61374.27 | H3: =COUNTIFS(Checks!$C$2:$C$97,A3,Checks!$Z$2:$Z$97,">0") -> 11
A4: V003 | B4: =IFERROR(INDEX(Vendors!$B$2:$B$11,MATCH(A4,Vendors!$A$2:$A$11,0)),"Not in vendor master") -> Lakeshore Envelope Co. | C4: =IFERROR(INDEX(Vendors!$E$2:$E$11,MATCH(A4,Vendors!$A$2:$A$11,0)),"") -> Active | D4: =COUNTIFS(Checks!$C$2:$C$97,A4,Checks!$M$2:$M$97,0) -> 12 | E4: =SUMIFS(Checks!$K$2:$K$97,Checks!$C$2:$C$97,A4,Checks!$M$2:$M$97,0) -> 52420.88 | F4: =SUMIFS(Checks!$W$2:$W$97,Checks!$C$2:$C$97,A4,Checks!$M$2:$M$97,0) -> 35916.49 | G4: =E4-F4 -> 16504.39 | H4: =COUNTIFS(Checks!$C$2:$C$97,A4,Checks!$Z$2:$Z$97,">0") -> 4
A5: V004 | B5: =IFERROR(INDEX(Vendors!$B$2:$B$11,MATCH(A5,Vendors!$A$2:$A$11,0)),"Not in vendor master") -> Summit Digital Print Inc. | C5: =IFERROR(INDEX(Vendors!$E$2:$E$11,MATCH(A5,Vendors!$A$2:$A$11,0)),"") -> Active | D5: =COUNTIFS(Checks!$C$2:$C$97,A5,Checks!$M$2:$M$97,0) -> 12 | E5: =SUMIFS(Checks!$K$2:$K$97,Checks!$C$2:$C$97,A5,Checks!$M$2:$M$97,0) -> 72748.45 | F5: =SUMIFS(Checks!$W$2:$W$97,Checks!$C$2:$C$97,A5,Checks!$M$2:$M$97,0) -> 53143.36 | G5: =E5-F5 -> 19605.09 | H5: =COUNTIFS(Checks!$C$2:$C$97,A5,Checks!$Z$2:$Z$97,">0") -> 3
A6: V005 | B6: =IFERROR(INDEX(Vendors!$B$2:$B$11,MATCH(A6,Vendors!$A$2:$A$11,0)),"Not in vendor master") -> Harbourview Postage Ltd. | C6: =IFERROR(INDEX(Vendors!$E$2:$E$11,MATCH(A6,Vendors!$A$2:$A$11,0)),"") -> Active | D6: =COUNTIFS(Checks!$C$2:$C$97,A6,Checks!$M$2:$M$97,0) -> 9 | E6: =SUMIFS(Checks!$K$2:$K$97,Checks!$C$2:$C$97,A6,Checks!$M$2:$M$97,0) -> 81929.04 | F6: =SUMIFS(Checks!$W$2:$W$97,Checks!$C$2:$C$97,A6,Checks!$M$2:$M$97,0) -> 38459.98 | G6: =E6-F6 -> 43469.06 | H6: =COUNTIFS(Checks!$C$2:$C$97,A6,Checks!$Z$2:$Z$97,">0") -> 6
A7: V006 | B7: =IFERROR(INDEX(Vendors!$B$2:$B$11,MATCH(A7,Vendors!$A$2:$A$11,0)),"Not in vendor master") -> Cedarline Paper Supply | C7: =IFERROR(INDEX(Vendors!$E$2:$E$11,MATCH(A7,Vendors!$A$2:$A$11,0)),"") -> Active | D7: =COUNTIFS(Checks!$C$2:$C$97,A7,Checks!$M$2:$M$97,0) -> 11 | E7: =SUMIFS(Checks!$K$2:$K$97,Checks!$C$2:$C$97,A7,Checks!$M$2:$M$97,0) -> 125079.76 | F7: =SUMIFS(Checks!$W$2:$W$97,Checks!$C$2:$C$97,A7,Checks!$M$2:$M$97,0) -> 93927.99 | G7: =E7-F7 -> 31151.77 | H7: =COUNTIFS(Checks!$C$2:$C$97,A7,Checks!$Z$2:$Z$97,">0") -> 4
A8: V007 | B8: =IFERROR(INDEX(Vendors!$B$2:$B$11,MATCH(A8,Vendors!$A$2:$A$11,0)),"Not in vendor master") -> Redwood Document Services | C8: =IFERROR(INDEX(Vendors!$E$2:$E$11,MATCH(A8,Vendors!$A$2:$A$11,0)),"") -> Inactive | D8: =COUNTIFS(Checks!$C$2:$C$97,A8,Checks!$M$2:$M$97,0) -> 4 | E8: =SUMIFS(Checks!$K$2:$K$97,Checks!$C$2:$C$97,A8,Checks!$M$2:$M$97,0) -> 23019.38 | F8: =SUMIFS(Checks!$W$2:$W$97,Checks!$C$2:$C$97,A8,Checks!$M$2:$M$97,0) -> 15771.04 | G8: =E8-F8 -> 7248.34 | H8: =COUNTIFS(Checks!$C$2:$C$97,A8,Checks!$Z$2:$Z$97,">0") -> 4
A9: V008 | B9: =IFERROR(INDEX(Vendors!$B$2:$B$11,MATCH(A9,Vendors!$A$2:$A$11,0)),"Not in vendor master") -> ClearPath Fulfillment | C9: =IFERROR(INDEX(Vendors!$E$2:$E$11,MATCH(A9,Vendors!$A$2:$A$11,0)),"") -> Active | D9: =COUNTIFS(Checks!$C$2:$C$97,A9,Checks!$M$2:$M$97,0) -> 8 | E9: =SUMIFS(Checks!$K$2:$K$97,Checks!$C$2:$C$97,A9,Checks!$M$2:$M$97,0) -> 69403.12 | F9: =SUMIFS(Checks!$W$2:$W$97,Checks!$C$2:$C$97,A9,Checks!$M$2:$M$97,0) -> 62328.05 | G9: =E9-F9 -> 7075.07 | H9: =COUNTIFS(Checks!$C$2:$C$97,A9,Checks!$Z$2:$Z$97,">0") -> 1
A10: V009 | B10: =IFERROR(INDEX(Vendors!$B$2:$B$11,MATCH(A10,Vendors!$A$2:$A$11,0)),"Not in vendor master") -> Granite Press Ltd. | C10: =IFERROR(INDEX(Vendors!$E$2:$E$11,MATCH(A10,Vendors!$A$2:$A$11,0)),"") -> Active | D10: =COUNTIFS(Checks!$C$2:$C$97,A10,Checks!$M$2:$M$97,0) -> 3 | E10: =SUMIFS(Checks!$K$2:$K$97,Checks!$C$2:$C$97,A10,Checks!$M$2:$M$97,0) -> 21910.04 | F10: =SUMIFS(Checks!$W$2:$W$97,Checks!$C$2:$C$97,A10,Checks!$M$2:$M$97,0) -> 21910.04 | G10: =E10-F10 -> 0 | H10: =COUNTIFS(Checks!$C$2:$C$97,A10,Checks!$Z$2:$Z$97,">0") -> 0
A11: V010 | B11: =IFERROR(INDEX(Vendors!$B$2:$B$11,MATCH(A11,Vendors!$A$2:$A$11,0)),"Not in vendor master") -> Bluewater Data Mail | C11: =IFERROR(INDEX(Vendors!$E$2:$E$11,MATCH(A11,Vendors!$A$2:$A$11,0)),"") -> Inactive | D11: =COUNTIFS(Checks!$C$2:$C$97,A11,Checks!$M$2:$M$97,0) -> 3 | E11: =SUMIFS(Checks!$K$2:$K$97,Checks!$C$2:$C$97,A11,Checks!$M$2:$M$97,0) -> 15561.53 | F11: =SUMIFS(Checks!$W$2:$W$97,Checks!$C$2:$C$97,A11,Checks!$M$2:$M$97,0) -> 14768.08 | G11: =E11-F11 -> 793.45 | H11: =COUNTIFS(Checks!$C$2:$C$97,A11,Checks!$Z$2:$Z$97,">0") -> 4
A12: UNKNOWN | B12: =IFERROR(INDEX(Vendors!$B$2:$B$11,MATCH(A12,Vendors!$A$2:$A$11,0)),"Not in vendor master") -> Not in vendor master | C12: =IFERROR(INDEX(Vendors!$E$2:$E$11,MATCH(A12,Vendors!$A$2:$A$11,0)),"") | D12: =COUNTIFS(Checks!$C$2:$C$97,A12,Checks!$M$2:$M$97,0) -> 2 | E12: =SUMIFS(Checks!$K$2:$K$97,Checks!$C$2:$C$97,A12,Checks!$M$2:$M$97,0) -> 11458.35 | F12: =SUMIFS(Checks!$W$2:$W$97,Checks!$C$2:$C$97,A12,Checks!$M$2:$M$97,0) -> 0 | G12: =E12-F12 -> 11458.35 | H12: =COUNTIFS(Checks!$C$2:$C$97,A12,Checks!$Z$2:$Z$97,">0") -> 2
A13: Total | D13: =SUM(D2:D12) -> 92 | E13: =SUM(E2:E12) -> 654664.51 | F13: =SUM(F2:F12) -> 440973.24 | G13: =SUM(G2:G12) -> 213691.27 | H13: =SUM(H2:H12) -> 42

Sheet Data_Dictionary
A1: Table | B1: Field | C1: Source | D1: Rule / Note
A2: Invoices | B2: InvoiceNo | C2: AP export 'Invoice #' | D2: Text, trimmed. Should be unique; repeats flagged as duplicate.
A3: Invoices | B3: VendorRaw | C3: AP export 'Vendor' | D3: Free text as keyed by AP; inconsistent spelling/case.
A4: Invoices | B4: InvoiceDate | C4: AP export | D4: 3 formats in source (2026-05-16, 2026/06/10, Sep 05, 2026) -> real date.
A5: Invoices | B5: NetAmount / Tax / InvoiceTotal | C5: AP export | D5: Stored as text with $, commas, spaces -> number.
A6: Checks | B6: VendorID | C6: Vendor_Aliases | D6: UPPER(TRIM(VendorRaw)) looked up in alias table; 'UNKNOWN' if no match.
A7: Checks | B7: DueDate | C7: Vendors.PaymentTerms | D7: InvoiceDate + term days (Net30 = 30). Unknown vendor defaults to 30.
A8: Checks | B8: Is_Duplicate | C8: Invoices | D8: 1 on 2nd+ occurrence of an InvoiceNo; first occurrence kept.
A9: Checks | B9: PO_Invoiced_ToDate | C9: Checks | D9: Sum of NetAmount of non-duplicate invoices on the same PO.
A10: Checks | B10: Flag_OverPO | C10: POs.Approved_Amount | D10: PO_Invoiced_ToDate > Approved_Amount (net of tax).
A11: Checks | B11: Flag_TotalMismatch | C11: Invoices | D11: |Net + Tax - Total| > $0.01.
A12: Checks | B12: Flag_TaxRate | C12: Vendors.Province | D12: Tax differs from ROUND(Net x provincial rate, 2) by > $0.01.
... A16: Vendor_Aliases | B16: AliasKey | C16: Built by analyst | D16: Catalog of every spelling seen in AP, mapped to the master VendorID.
